#Go 逃逸分析



##例子1：



```
func e1() {
	var err error
	defer fmt.Println(err)
	err = errors.New("e1")
	return
}
func e2() {
	var err error
	defer func() {
		fmt.Println(err)
	}() // 这里是一个闭包，里面的err只是对外面err的引用，捕获了err
	err = errors.New("e2")
	return
}

func e3() {
	var err error
	defer func(err error) {
		fmt.Println(err)
	}(err) // 代码运行时已经在这里把nil赋值进去了
	err = errors.New("e3")
	return
}
func main() {
	e1()
	e2()
	e3()
}
```



```
//打印结果
<nil>
e2
<nil>
```



##例子2



```
func accumulator() func(int) int {
	var x int
	return func(delta int) int {
		fmt.Println(&x, x)
		x += delta
		return x
	}
}

func main() {
	var a = accumulator()

	fmt.Printf("%d\n", a(1))
	fmt.Printf("%d\n", a(10))
	fmt.Printf("%d\n", a(100))

	var b = accumulator()

	fmt.Printf("%d\n", b(1))
	fmt.Printf("%d\n", b(10))
	fmt.Printf("%d\n", b(100))

}
```





```
输出
0xc0000120a0 0
1
0xc0000120a0 1
11
0xc0000120a0 11
111
0xc0000120e0 0
1
0xc0000120e0 1
11
0xc0000120e0 11
111
```



分析：

* 函数accumulator和返回值形成闭包，当编译器发现x在外部被调用时把x放到了堆上。所以前三次打印的地址是一样的。并且x的值也会依次增加
* 当第二次生成函数b时，这里的a和b里面的x已经是两个不同的地址了，但他们都在堆上。



实例之间是不影响的，但在每个实例内部x指向的变量是同一个







